<?xml version='1.0'?>
<robot xmlns:xacro="http://www.ros.org/wiki/xacro">
    <xacro:macro name="grip_base" params="parent">
        <link name="base_grip">
            <collision>
                <origin xyz="0 0 0" rpy="0 0 0" />
                <geometry>
                    <box size="0.2 0.05 0.05" />
                </geometry>
            </collision>

            <visual>
                <origin xyz="0 0 0" rpy="0 0 0" />
                <geometry>
                    <box size="0.2 0.1 0.05" />
                </geometry>
            </visual>

            <inertial>
                <mass value="1e-5" />
                <origin xyz="0 0 0" rpy="0 0 0" />
                <inertia ixx="1e-6" ixy="0" ixz="0" iyy="1e-6" iyz="0" izz="1e-6" />
            </inertial>
        </link>

        <joint name="base_grip_joint" type="prismatic">
            <origin rpy="0 0 0" xyz="0.06 0.0 0.07" />
            <limit effort="1000.0" lower="0" upper="0.1" velocity="0.5" />
            <axis xyz="1 0 0" />
            <parent link="${parent}" />
            <child link="base_grip" />
        </joint>
    </xacro:macro>
</robot>