<?xml version='1.0'?>
<robot xmlns:xacro="http://www.ros.org/wiki/xacro">
    <xacro:macro name="finger" params="parent prefix lower upper offset">
        <link name="finger_${prefix}_grip">
            <collision>
                <origin xyz="0.05 ${offset} 0" rpy="0 0 0" />
                <geometry>
                    <box size="0.1 0.02 0.05" />
                </geometry>
            </collision>

            <visual>
                <origin xyz="0.05 ${offset} 0" rpy="0 0 0" />
                <geometry>
                    <box size="0.1 0.02 0.05" />
                </geometry>
            </visual>

            <inertial>
                <mass value="1e-5" />
                <origin xyz="0 0 0" rpy="0 0 0" />
                <inertia ixx="1e-6" ixy="0" ixz="0" iyy="1e-6" iyz="0" izz="1e-6" />
            </inertial>
        </link>

        <joint name="finger_${prefix}_joint" type="revolute">
            <origin rpy="0 0 0" xyz="0.1 ${offset} 0.0" />
            <limit effort="1000.0" lower="${lower}" upper="${upper}" velocity="0.5" />
            <axis xyz="0 0 1" />
            <parent link="${parent}" />
            <child link="finger_${prefix}_grip" />
        </joint>
    </xacro:macro>
</robot>